Fixed bug when using wit.ai training data to train.
Training failed with an error similarly to this:

```bash
  File "./venv/lib/python3.8/site-packages/rasa/nlu/classifiers/diet_classifier.py", line 803, in train
    self.check_correct_entity_annotations(training_data)
  File "./venv/lib/python3.8/site-packages/rasa/nlu/extractors/extractor.py", line 418, in check_correct_entity_annotations
    entities_repr = [
  File "./venv/lib/python3.8/site-packages/rasa/nlu/extractors/extractor.py", line 422, in <listcomp>
    entity[ENTITY_ATTRIBUTE_VALUE],
KeyError: 'value'
```