Updated `asyncio.Task.all_tasks` to `asyncio.all_tasks`, with a fallback for python 3.6, which raises an AtributeError for `asyncio.all_tasks`.
